Simulations:   0%|          | 0/100 [00:00<?, ?it/s]Simulations:   0%|          | 0/100 [00:00<?, ?it/s]
Traceback (most recent call last):
  File "/homes/simondn/.local/lib/python3.9/site-packages/pandas/core/indexes/base.py", line 3805, in get_loc
    return self._engine.get_loc(casted_key)
  File "index.pyx", line 167, in pandas._libs.index.IndexEngine.get_loc
  File "index.pyx", line 196, in pandas._libs.index.IndexEngine.get_loc
  File "pandas/_libs/hashtable_class_helper.pxi", line 7081, in pandas._libs.hashtable.PyObjectHashTable.get_item
  File "pandas/_libs/hashtable_class_helper.pxi", line 7089, in pandas._libs.hashtable.PyObjectHashTable.get_item
KeyError: 'Y'

The above exception was the direct cause of the following exception:

Traceback (most recent call last):
  File "/mnt/beegfs/homes/simondn/WeightedGreedySampling/Code/RunSimulation.py", line 26, in <module>
    SimulationResults = RunSimulationFunction(
  File "/mnt/beegfs/homes/simondn/WeightedGreedySampling/Code/utils/Main/RunSimulationFunction.py", line 63, in RunSimulationFunction
    results = OneIterationFunction(SimulationConfigInput)
  File "/mnt/beegfs/homes/simondn/WeightedGreedySampling/Code/utils/Main/OneIterationFunction.py", line 41, in OneIterationFunction
    df_Train, df_Test, df_Candidate = TrainTestCandidateSplit(df, 
  File "/mnt/beegfs/homes/simondn/WeightedGreedySampling/Code/utils/Main/TrainTestCandidateSplit.py", line 19, in TrainTestCandidateSplit
    df.loc[:, df.columns != "Y"], df["Y"], test_size=TestProportion)
  File "/homes/simondn/.local/lib/python3.9/site-packages/pandas/core/frame.py", line 4102, in __getitem__
    indexer = self.columns.get_loc(key)
  File "/homes/simondn/.local/lib/python3.9/site-packages/pandas/core/indexes/base.py", line 3812, in get_loc
    raise KeyError(key) from err
KeyError: 'Y'
